#VRML_SIM R2023a utf8

EXTERNPROTO "https://raw.githubusercontent.com/cyberbotics/webots/R2023a/projects/objects/backgrounds/protos/TexturedBackground.proto"
EXTERNPROTO "https://raw.githubusercontent.com/cyberbotics/webots/R2023a/projects/objects/backgrounds/protos/TexturedBackgroundLight.proto"
EXTERNPROTO "https://raw.githubusercontent.com/cyberbotics/webots/R2023a/projects/objects/floors/protos/Floor.proto"
EXTERNPROTO "https://raw.githubusercontent.com/cyberbotics/webots/R2023a/projects/objects/drinks/protos/Can.proto"
EXTERNPROTO "https://raw.githubusercontent.com/cyberbotics/webots/R2023a/projects/objects/apartment_structure/protos/Wall.proto"

WorldInfo {
  basicTimeStep 16
}
Viewpoint {
  orientation 0 0 -1 1.5707963267948966
  position 0.21237129635615845 2.025588795975746 0.2297593061673883
  follow "robot:box_wall_2"
}
TexturedBackground {
}
TexturedBackgroundLight {
}
Robot {
  translation 0.1511350224562413 0.00015074689286709628 0.1967330785834158
  rotation 0.0177097260589031 0.986683373736197 0.16168576188234757 0.003620842168338538
  children [
    Camera {
      translation 0.2 0 0.2
    }
    DEF Tyres Group {
      children [
        HingeJoint {
          jointParameters HingeJointParameters {
            position 121.95960156800452
            axis 0 1 0
            anchor 0 0.25 -0.15
          }
          device [
            RotationalMotor {
              name "wheel_left1"
            }
          ]
          endPoint Solid {
            translation 0.0005580432238579539 0.25002800048994067 -0.14994786504614507
            rotation 0.24548238047555226 0.6844121004524639 -0.6865263852397098 2.6613152675035083
            children [
              DEF wheel_shape Shape {
                appearance PBRAppearance {
                  baseColor 1 0.220691 0.0788586
                  roughness 1
                  metalness 0
                }
                geometry Cylinder {
                  height 0.05
                  radius 0.05
                }
              }
            ]
            boundingObject USE wheel_shape
            physics Physics {
            }
          }
        }
        HingeJoint {
          jointParameters HingeJointParameters {
            position 66.04797694869438
            axis 0 1 0
            anchor -0.4 0.25 -0.15
          }
          device [
            RotationalMotor {
              name "wheel_left2"
            }
          ]
          endPoint Solid {
            translation -0.40001024392398293 0.2500639633922303 -0.1500749818818764
            rotation 0.01858997483994441 0.7062267865088423 -0.7077415763206544 3.1074875762559175
            children [
              DEF wheel_shape Shape {
                appearance PBRAppearance {
                  baseColor 1 0.220691 0.0788586
                  roughness 1
                  metalness 0
                }
                geometry Cylinder {
                  height 0.05
                  radius 0.05
                }
              }
            ]
            name "solid(3)"
            boundingObject USE wheel_shape
            physics Physics {
            }
          }
        }
        HingeJoint {
          jointParameters HingeJointParameters {
            position 3.0079902897404214
            axis 0 1 0
            anchor 0 -0.25 -0.15
          }
          device [
            RotationalMotor {
              name "wheel_right1"
            }
          ]
          endPoint Solid {
            translation 9.242473292735436e-06 -0.2500600011721518 -0.15006107168629118
            rotation 0.09220914619059264 0.7032571934064412 -0.7049303464037404 2.960393774686188
            children [
              DEF wheel_shape Shape {
                appearance PBRAppearance {
                  baseColor 1 0.220691 0.0788586
                  roughness 1
                  metalness 0
                }
                geometry Cylinder {
                  height 0.05
                  radius 0.05
                }
              }
            ]
            name "solid(4)"
            boundingObject USE wheel_shape
            physics Physics {
            }
          }
        }
        HingeJoint {
          jointParameters HingeJointParameters {
            position 3.0079973647711684
            axis 0 1 0
            anchor -0.39998 -0.250064 -0.149921
          }
          device [
            RotationalMotor {
              name "wheel_right2"
            }
          ]
          endPoint Solid {
            translation -0.3999808249190252 -0.25006400024400366 -0.14991501867313703
            rotation 0.09220679747588639 0.7032573589046544 -0.7049304885204578 2.9603990791907635
            children [
              DEF wheel_shape Shape {
                appearance PBRAppearance {
                  baseColor 1 0.220691 0.0788586
                  roughness 1
                  metalness 0
                }
                geometry Cylinder {
                  height 0.05
                  radius 0.05
                }
              }
            ]
            name "solid(5)"
            boundingObject USE wheel_shape
            physics Physics {
            }
          }
        }
      ]
    }
    HingeJoint {
      jointParameters HingeJointParameters {
        position 43.98175553341993
        axis 0 1 0
        anchor 0.22 0 0
      }
      device [
        PositionSensor {
          name "sweeper_position_sensor"
        }
        RotationalMotor {
          name "sweeper_motor"
        }
      ]
      endPoint Solid {
        translation 0.2199280484046084 5.231219637470962e-05 0.00019758740285578187
        rotation 0.0003026113884198937 0.9999968232326879 -0.0025023890344862613 6.276090884598602
        children [
          DEF d_left Solid {
            translation 0 0.15 -0.16
            children [
              DEF distance_sensor_shape Shape {
                appearance PBRAppearance {
                  baseColor 0 0 0
                  roughness 1
                  metalness 0
                }
                geometry Box {
                  size 0.03 0.02 0.02
                }
              }
              DistanceSensor {
                name "distance_sensor_left"
                lookupTable [
                  0 0 0
                  0.2 100 0
                ]
              }
            ]
          }
          DEF d_right Solid {
            translation -0.000509661 -0.17 -0.16
            children [
              DEF distance_sensor_shape Shape {
                appearance PBRAppearance {
                  baseColor 0 0 0
                  roughness 1
                  metalness 0
                }
                geometry Box {
                  size 0.03 0.02 0.02
                }
              }
              DistanceSensor {
                name "distance_sensor_right"
                lookupTable [
                  0 0 0
                  0.2 100 0
                ]
              }
            ]
          }
          DEF d_center Solid {
            translation -0.000175194 0.04 -0.16
            children [
              DEF distance_sensor_shape Shape {
                appearance PBRAppearance {
                  baseColor 0 0 0
                  roughness 1
                  metalness 0
                }
                geometry Box {
                  size 0.03 0.02 0.02
                }
              }
              DistanceSensor {
                name "distance_sensor_center"
                lookupTable [
                  0 0 0
                  0.2 100 0
                ]
              }
            ]
          }
          DEF d_center2 Solid {
            translation -0.000350391 -0.07 -0.16
            children [
              DEF distance_sensor_shape Shape {
                appearance PBRAppearance {
                  baseColor 0 0 0
                  roughness 1
                  metalness 0
                }
                geometry Box {
                  size 0.03 0.02 0.02
                }
              }
              DistanceSensor {
                name "distance_sensor_center_2"
                lookupTable [
                  0 0 0
                  0.2 100 0
                ]
              }
            ]
            name "solid(1)"
          }
          DEF sweeper_shape Shape {
            appearance PBRAppearance {
              roughness 1
              metalness 0
            }
            geometry Box {
              size 0.02 0.4 0.37
            }
          }
        ]
        name "solid(2)"
        boundingObject USE sweeper_shape
        physics Physics {
        }
      }
    }
    Group {
      children [
        Solid {
          translation -1.85717e-06 8.4367e-17 -0.0301247
          rotation 2.8834614090237705e-08 -0.9999999999999996 -9.6654458917076e-10 9.827436276334678e-08
          children [
            DEF box_wall Shape {
              appearance PBRAppearance {
                roughness 1
                metalness 0
              }
              geometry Box {
                size 0.02 0.4 0.3
              }
            }
          ]
          name "box_wall_1"
          boundingObject USE box_wall
        }
        Solid {
          translation -0.1 0.2 -6.2784e-06
          rotation 1.139551427790092e-15 -1.6955323793011871e-15 1 1.5699999999999998
          children [
            Shape {
              appearance PBRAppearance {
                roughness 1
                metalness 0
              }
              geometry DEF box_wall Box {
                size 0.02 0.6 0.4
              }
            }
            DEF d_left Solid {
              translation 0 0.06 -0.16
              children [
                DEF distance_sensor_shape Shape {
                  appearance PBRAppearance {
                    baseColor 0 0 0
                    roughness 1
                    metalness 0
                  }
                  geometry Box {
                    size 0.03 0.02 0.02
                  }
                }
                DistanceSensor {
                  name "distance_sensor_left_wall"
                  lookupTable [
                    0 0 0
                    0.2 100 0
                  ]
                }
              ]
            }
          ]
          name "box_wall_2"
          boundingObject USE box_wall
        }
        Solid {
          translation -0.1 -0.2 -6.2784e-06
          rotation 1.139551427790092e-15 -1.6955323793011871e-15 1 1.5699999999999998
          children [
            DEF d_right Solid {
              translation -0.000143345 0.06 -0.16
              rotation 0 0 1 3.14
              children [
                DEF distance_sensor_shape Shape {
                  appearance PBRAppearance {
                    baseColor 0 0 0
                    roughness 1
                    metalness 0
                  }
                  geometry Box {
                    size 0.03 0.02 0.02
                  }
                }
                DistanceSensor {
                  name "distance_sensor_right_wall"
                  lookupTable [
                    0 0 0
                    0.2 100 0
                  ]
                }
              ]
            }
            Shape {
              appearance PBRAppearance {
                roughness 1
                metalness 0
              }
              geometry DEF box_wall Box {
                size 0.02 0.6 0.4
              }
            }
          ]
          name "box_wall_3"
          boundingObject USE box_wall
        }
        Solid {
          translation -0.4 -3.55826007184602e-21 -6.278396306458323e-06
          rotation 0.9807014561659081 -0.19272835386804643 -0.032869978542439886 2.889496319432257e-15
          children [
            DEF d_back Solid {
              translation -0.000334464 -0.15 -0.16
              rotation 0 0 1 3.14
              children [
                DEF distance_sensor_shape Shape {
                  appearance PBRAppearance {
                    baseColor 0 0 0
                    roughness 1
                    metalness 0
                  }
                  geometry Box {
                    size 0.03 0.02 0.02
                  }
                }
                DistanceSensor {
                  name "distance_sensor_back_wall"
                  lookupTable [
                    0 0 0
                    0.2 100 0
                  ]
                }
              ]
            }
            DEF d_back Solid {
              translation 0.000127412 0.14 -0.16
              rotation 0 0 1 3.14
              children [
                DEF distance_sensor_shape Shape {
                  appearance PBRAppearance {
                    baseColor 0 0 0
                    roughness 1
                    metalness 0
                  }
                  geometry Box {
                    size 0.03 0.02 0.02
                  }
                }
                DistanceSensor {
                  name "distance_sensor_back_wall_2"
                  lookupTable [
                    0 0 0
                    0.2 100 0
                  ]
                }
              ]
              name "solid(1)"
            }
            DEF box_wall Shape {
              appearance PBRAppearance {
                roughness 1
                metalness 0
              }
              geometry Box {
                size 0.02 0.4 0.4
              }
            }
          ]
          name "box_wall_4"
          boundingObject USE box_wall
        }
        Solid {
          translation -0.2 0 -0.18
          rotation 0 1 0 1.57
          children [
            DEF box_floor Shape {
              appearance PBRAppearance {
                roughness 1
                metalness 0
              }
              geometry Box {
                size 0.02 0.4 0.4
              }
            }
          ]
          name "box_floor"
          boundingObject USE box_floor
          physics Physics {
            mass 20
          }
        }
      ]
    }
    SliderJoint {
      jointParameters JointParameters {
      }
      device [
        PositionSensor {
          name "slider_position"
        }
        LinearMotor {
          name "slab_linear_motor"
        }
      ]
      endPoint Solid {
        rotation -3.765839153279543e-08 -0.9999999999999993 -2.498924693683275e-10 8.091120447688148e-07
        children [
          HingeJoint {
            jointParameters HingeJointParameters {
              position 0.00019391029432280074
              axis 0 1 0
              anchor 0 0 -0.19
            }
            device [
              PositionSensor {
                name "slab_rotational_position"
              }
              RotationalMotor {
                name "slab_rotational_motor"
              }
            ]
            endPoint Solid {
              translation 0.12 6.6567e-16 -0.2
              rotation 0 1 0 0.00019391029416036622
              children [
                DEF sliding_slab_shape Shape {
                  appearance PBRAppearance {
                    roughness 1
                    metalness 0
                  }
                  geometry Box {
                    size 0.2 0.4 0.02
                  }
                }
              ]
              boundingObject USE sliding_slab_shape
            }
          }
        ]
        name "solid(1)"
      }
    }
  ]
  physics Physics {
  }
  controller "robot_controller"
}
Floor {
}
Wall {
  translation 5 0 0
  size 0.2 10 1
}
Wall {
  translation -5 0 0
  name "wall(1)"
  size 0.2 10 1
}
Wall {
  translation 0 5 0
  rotation 0 0 1 1.5708
  name "wall(2)"
  size 0.2 10 1
}
Wall {
  translation 0 -5 0
  rotation 0 0 1 1.5708
  name "wall(3)"
  size 0.2 10 1
}
Can {
  translation 0.22423221319583733 -0.0017411375504410968 0.03809248577846834
  rotation -0.4332477243558811 -0.6371867914208076 -0.6374083480621406 2.3243282845359317
}
