#VRML_SIM R2023a utf8

EXTERNPROTO "https://raw.githubusercontent.com/cyberbotics/webots/R2023a/projects/objects/floors/protos/RectangleArena.proto"
EXTERNPROTO "https://raw.githubusercontent.com/cyberbotics/webots/R2023a/projects/appearances/protos/Parquetry.proto"
EXTERNPROTO "https://raw.githubusercontent.com/cyberbotics/webots/R2023a/projects/appearances/protos/BrushedAluminium.proto"
EXTERNPROTO "../protos/Can.proto"

WorldInfo {
}
Viewpoint {
  orientation -0.09667372605885306 -0.09603596998839313 0.9906721370656824 4.696428420447386
  position 0.37567368377722227 2.504824010476001 0.4736173281092623
}
RectangleArena {
  name "arena"
  floorSize 2 2
  floorAppearance Parquetry {
    type "dark strip"
    colorOverride 0.382208 0.312245 0.26453
  }
  wallHeight 0
  wallAppearance BrushedAluminium {
    colorOverride 1 0.174411 0.0675059
    IBLStrength 7
  }
}
DEF ROBOT Robot {
  translation 0.129987 -0.00134104 0.203002
  rotation 0.5856198139025262 -0.7971130864897652 -0.14717391382826997 0.017459672891677037
  children [
    HingeJoint {
      jointParameters HingeJointParameters {
        position -0.0039050965210123026
      }
      device [
        RotationalMotor {
        }
      ]
      endPoint Solid {
        translation 0 0.0012871566376685246 -0.12999362764301214
        rotation 0.024861357274360736 0.9996786579316541 0.004949120168631283 0.39312309966625597
        children [
          DEF up_inclination_shape Shape {
            appearance PBRAppearance {
            }
            geometry Box {
              size 0.4 0.4 0.001
            }
          }
        ]
        name "solid(5)"
        boundingObject USE up_inclination_shape
        physics Physics {
        }
      }
    }
    DEF Sweeper HingeJoint {
      jointParameters HingeJointParameters {
        position 213.8353545495386
        axis 0 1 0
        anchor 0.2 0 0
      }
      device [
        RotationalMotor {
          name "sweeper"
        }
      ]
      endPoint Solid {
        translation 0.2786241324132115 -5.171628591480302e-07 -0.016199781809681884
        rotation 5.4987167715470215e-05 -0.999999998417949 1.1853824474574941e-05 6.116944111178439
        children [
          DEF sweeper_shape Shape {
            appearance PBRAppearance {
            }
            geometry Box {
              size 0.2 0.38 0.001
            }
          }
        ]
        name "solid(4)"
        boundingObject USE sweeper_shape
        physics Physics {
        }
      }
    }
    Camera {
      translation 0.1 0 0.025
    }
    DEF l2 HingeJoint {
      jointParameters HingeJointParameters {
        position 23.5109175764347
        axis 0 1 0
        anchor -0.15 -0.225 -0.16
      }
      device [
        RotationalMotor {
          name "wheell2"
        }
      ]
      endPoint Solid {
        translation -0.15 -0.225 -0.16
        rotation 0.5577129317061158 -0.5869220792065952 0.5869231284824074 2.124103063715591
        children [
          DEF WHEEL Shape {
            appearance PBRAppearance {
              baseColor 0 0.137758 1
              metalness 0
            }
            geometry Cylinder {
              height 0.05
              radius 0.05
            }
          }
        ]
        name "solid(3)"
        boundingObject DEF WHEEL Shape {
          appearance PBRAppearance {
            baseColor 0 0.137758 1
            metalness 0
          }
          geometry Cylinder {
            height 0.02
            radius 0.04
          }
        }
        physics Physics {
        }
      }
    }
    DEF l1 HingeJoint {
      jointParameters HingeJointParameters {
        position 23.541421805926483
        axis 0 1 0
        anchor 0.15 -0.225 -0.16
      }
      device [
        RotationalMotor {
          name "wheell1"
        }
      ]
      endPoint Solid {
        translation 0.15 -0.225 -0.16
        rotation 0.5694518148958573 -0.5812581820657186 0.5812603171501304 2.1062864625313575
        children [
          DEF WHEEL Shape {
            appearance PBRAppearance {
              baseColor 0 0.137758 1
              metalness 0
            }
            geometry Cylinder {
              height 0.05
              radius 0.05
            }
          }
        ]
        name "solid(2)"
        boundingObject USE WHEEL
        physics Physics {
        }
      }
    }
    DEF r2 HingeJoint {
      jointParameters HingeJointParameters {
        position 23.499415091151352
        axis 0 1 0
        anchor -0.15 0.225 -0.16
      }
      device [
        RotationalMotor {
          name "wheelr2"
        }
      ]
      endPoint Solid {
        translation -0.15 0.225 -0.16
        rotation 0.5532882527169912 -0.5890116979614443 0.5890138615261573 2.130867215053557
        children [
          DEF WHEEL Shape {
            appearance PBRAppearance {
              baseColor 0 0.137758 1
              metalness 0
            }
            geometry Cylinder {
              height 0.05
              radius 0.05
            }
          }
        ]
        name "solid(1)"
        boundingObject USE WHEEL
        physics Physics {
        }
      }
    }
    DEF r1 HingeJoint {
      jointParameters HingeJointParameters {
        position 23.518858287470614
        axis 0 1 0
        anchor 0.15 0.225 -0.16
      }
      device [
        RotationalMotor {
          name "wheelr1"
        }
      ]
      endPoint Solid {
        translation 0.15 0.225 -0.16
        rotation 0.560768591466451 -0.5854639479510831 0.5854660984841601 2.119449321022626
        children [
          DEF WHEEL Shape {
            appearance PBRAppearance {
              baseColor 0 0.137758 1
              metalness 0
            }
            geometry Cylinder {
              height 0.05
              radius 0.05
            }
          }
        ]
        boundingObject USE WHEEL
        physics Physics {
        }
      }
    }
  ]
  physics Physics {
    mass 30
  }
  controller "robot_controller"
  selfCollision TRUE
}
DirectionalLight {
  direction 0 -1 -1
  intensity 7
  castShadows TRUE
}
Background {
  skyColor [
    0.164935 0.191836 0.241779
  ]
  luminosity 2
}
Robot {
  name "supervisor"
  controller "image_capture_supervisor"
  supervisor TRUE
}
Can {
  translation 0.4038640000000004 0.1288800000000144 0.031475320057788726
  rotation -0.5841427650276946 -0.5631712895073481 0.5844786811684668 -2.116323592662531
}
