#VRML_SIM R2023a utf8

EXTERNPROTO "https://raw.githubusercontent.com/cyberbotics/webots/R2023a/projects/objects/backgrounds/protos/TexturedBackground.proto"
EXTERNPROTO "https://raw.githubusercontent.com/cyberbotics/webots/R2023a/projects/objects/backgrounds/protos/TexturedBackgroundLight.proto"
EXTERNPROTO "https://raw.githubusercontent.com/cyberbotics/webots/R2023a/projects/objects/floors/protos/Floor.proto"
EXTERNPROTO "https://raw.githubusercontent.com/cyberbotics/webots/R2023a/projects/objects/drinks/protos/Can.proto"
EXTERNPROTO "https://raw.githubusercontent.com/cyberbotics/webots/R2023a/projects/objects/apartment_structure/protos/Wall.proto"
EXTERNPROTO "https://raw.githubusercontent.com/cyberbotics/webots/R2023a/projects/appearances/protos/Parquetry.proto"

WorldInfo {
  basicTimeStep 16
}
Viewpoint {
  orientation -0.4944138168677724 -0.01665655909536119 0.8690670496166238 3.200132815658069
  position -2.16509133968988 2.5444562965496256 3.065867812289651
  follow "robot"
}
TexturedBackground {
}
TexturedBackgroundLight {
}
Robot {
  translation -3.76332 2.24417 0.197077
  rotation 0.0012180201471315825 -0.000524247063326785 0.9999991207955824 -0.8572953071795864
  children [
    Display {
      name "camera_display"
    }
    Camera {
      translation 0.245 0 0.25598
      rotation 0 1 0 0.523593
      children [
        Shape {
          appearance PBRAppearance {
            baseColor 1 0.0561074 0
            roughness 1
            metalness 0
          }
          geometry Box {
            size 0.05 0.05 0.05
          }
        }
      ]
      fieldOfView 2
      recognition Recognition {
      }
    }
    DEF Tyres Group {
      children [
        HingeJoint {
          jointParameters HingeJointParameters {
            position 930.0988410880568
            axis 0 1 0
            anchor 0 0.25 -0.15
          }
          device [
            RotationalMotor {
              name "wheel_left1"
            }
          ]
          endPoint Solid {
            translation -0.00048441709218507994 0.2500280040275398 -0.14970163552539698
            rotation -0.9990133610452689 -0.03126661362689149 0.031538917631102344 4.708386677493348
            children [
              DEF wheel_shape Shape {
                appearance PBRAppearance {
                  baseColor 1 0.220691 0.0788586
                  roughness 1
                  metalness 0
                }
                geometry Cylinder {
                  height 0.05
                  radius 0.05
                }
              }
            ]
            boundingObject USE wheel_shape
            physics Physics {
            }
          }
        }
        HingeJoint {
          jointParameters HingeJointParameters {
            position 874.2407354712725
            axis 0 1 0
            anchor -0.4 0.25 -0.15
          }
          device [
            RotationalMotor {
              name "wheel_left2"
            }
          ]
          endPoint Solid {
            translation -0.39996340865824087 0.25006396525611435 -0.14997911167768524
            rotation -0.8731342547174076 -0.3452441732109341 0.34415553766135404 4.574132648543851
            children [
              DEF wheel_shape Shape {
                appearance PBRAppearance {
                  baseColor 1 0.220691 0.0788586
                  roughness 1
                  metalness 0
                }
                geometry Cylinder {
                  height 0.05
                  radius 0.05
                }
              }
            ]
            name "solid(3)"
            boundingObject USE wheel_shape
            physics Physics {
            }
          }
        }
        HingeJoint {
          jointParameters HingeJointParameters {
            position 752.5744408569319
            axis 0 1 0
            anchor 0 -0.25 -0.15
          }
          device [
            RotationalMotor {
              name "wheel_right1"
            }
          ]
          endPoint Solid {
            translation -1.2377713226479914e-06 -0.250059997448572 -0.15000904999794248
            rotation 0.592199639471017 -0.5685704135721293 0.5709879787007912 2.0731816709419655
            children [
              DEF wheel_shape Shape {
                appearance PBRAppearance {
                  baseColor 1 0.220691 0.0788586
                  roughness 1
                  metalness 0
                }
                geometry Cylinder {
                  height 0.05
                  radius 0.05
                }
              }
            ]
            name "solid(4)"
            boundingObject USE wheel_shape
            physics Physics {
            }
          }
        }
        HingeJoint {
          jointParameters HingeJointParameters {
            position 752.5743496602965
            axis 0 1 0
            anchor -0.39998 -0.250064 -0.149921
          }
          device [
            RotationalMotor {
              name "wheel_right2"
            }
          ]
          endPoint Solid {
            translation -0.39994373759493385 -0.2500639985446977 -0.14993109516836192
            rotation 0.5921644381084217 -0.5685885667337168 0.5710064097883972 2.0732332620042575
            children [
              DEF wheel_shape Shape {
                appearance PBRAppearance {
                  baseColor 1 0.220691 0.0788586
                  roughness 1
                  metalness 0
                }
                geometry Cylinder {
                  height 0.05
                  radius 0.05
                }
              }
            ]
            name "solid(5)"
            boundingObject USE wheel_shape
            physics Physics {
            }
          }
        }
      ]
    }
    HingeJoint {
      jointParameters HingeJointParameters {
        position 62.831311545602944
        axis 0 1 0
        anchor 0.22 0 0
      }
      device [
        PositionSensor {
          name "sweeper_position_sensor"
        }
        RotationalMotor {
          name "sweeper_motor"
        }
      ]
      endPoint Solid {
        translation 0.21992694967286575 5.231059160910489e-05 0.00015051437475498085
        rotation -0.00035527369021282296 -0.9999968209128903 0.002496386331849695 0.007094331308470422
        children [
          DEF d_left Solid {
            translation 0 0.15 -0.16
            children [
              DEF distance_sensor_shape Shape {
                appearance PBRAppearance {
                  baseColor 0 0 0
                  roughness 1
                  metalness 0
                }
                geometry Box {
                  size 0.03 0.02 0.02
                }
              }
              DistanceSensor {
                name "distance_sensor_left"
                lookupTable [
                  0 0 0
                  0.4 100 0
                ]
              }
            ]
          }
          DEF d_right Solid {
            translation -0.000509661 -0.17 -0.16
            children [
              DEF distance_sensor_shape Shape {
                appearance PBRAppearance {
                  baseColor 0 0 0
                  roughness 1
                  metalness 0
                }
                geometry Box {
                  size 0.03 0.02 0.02
                }
              }
              DistanceSensor {
                name "distance_sensor_right"
                lookupTable [
                  0 0 0
                  0.4 100 0
                ]
              }
            ]
          }
          DEF d_center Solid {
            translation -0.000175194 0.04 -0.16
            children [
              DEF distance_sensor_shape Shape {
                appearance PBRAppearance {
                  baseColor 0 0 0
                  roughness 1
                  metalness 0
                }
                geometry Box {
                  size 0.03 0.02 0.02
                }
              }
              DistanceSensor {
                name "distance_sensor_center"
                lookupTable [
                  0 0 0
                  0.4 100 0
                ]
              }
            ]
          }
          DEF d_center2 Solid {
            translation -0.000350391 -0.07 -0.16
            children [
              DEF distance_sensor_shape Shape {
                appearance PBRAppearance {
                  baseColor 0 0 0
                  roughness 1
                  metalness 0
                }
                geometry Box {
                  size 0.03 0.02 0.02
                }
              }
              DistanceSensor {
                name "distance_sensor_center_2"
                lookupTable [
                  0 0 0
                  0.4 100 0
                ]
                type "sonar"
              }
            ]
            name "solid(1)"
          }
          DEF sweeper_shape Shape {
            appearance PBRAppearance {
              roughness 1
              metalness 0
            }
            geometry Box {
              size 0.02 0.4 0.37
            }
          }
        ]
        name "solid(2)"
        boundingObject USE sweeper_shape
        physics Physics {
        }
      }
    }
    Group {
      children [
        Solid {
          translation -0.150002 9.86152e-17 -0.0301247
          rotation 2.8834614090237705e-08 -0.9999999999999996 -9.6654458917076e-10 9.827436276334678e-08
          children [
            DEF box_wall Shape {
              appearance PBRAppearance {
                roughness 1
                metalness 0
              }
              geometry Box {
                size 0.02 0.4 0.3
              }
            }
          ]
          name "box_wall_1"
          boundingObject USE box_wall
        }
        Solid {
          translation -0.1 0.2 -6.2784e-06
          rotation 1.139551427790092e-15 -1.6955323793011871e-15 1 1.5699999999999998
          children [
            Shape {
              appearance PBRAppearance {
                roughness 1
                metalness 0
              }
              geometry DEF box_wall Box {
                size 0.02 0.6 0.4
              }
            }
            DEF d_left Solid {
              translation 0 0.06 -0.16
              children [
                DEF distance_sensor_shape Shape {
                  appearance PBRAppearance {
                    baseColor 0 0 0
                    roughness 1
                    metalness 0
                  }
                  geometry Box {
                    size 0.03 0.02 0.02
                  }
                }
                DistanceSensor {
                  name "distance_sensor_left_wall"
                  lookupTable [
                    0 0 0
                    0.4 100 0
                  ]
                }
              ]
            }
          ]
          name "box_wall_2"
          boundingObject USE box_wall
        }
        Solid {
          translation -0.1 -0.2 -6.2784e-06
          rotation 1.139551427790092e-15 -1.6955323793011871e-15 1 1.5699999999999998
          children [
            DEF d_right Solid {
              translation -0.000143345 0.06 -0.16
              rotation 0 0 1 3.14
              children [
                DEF distance_sensor_shape Shape {
                  appearance PBRAppearance {
                    baseColor 0 0 0
                    roughness 1
                    metalness 0
                  }
                  geometry Box {
                    size 0.03 0.02 0.02
                  }
                }
                DistanceSensor {
                  name "distance_sensor_right_wall"
                  lookupTable [
                    0 0 0
                    0.4 100 0
                  ]
                }
              ]
            }
            Shape {
              appearance PBRAppearance {
                roughness 1
                metalness 0
              }
              geometry DEF box_wall Box {
                size 0.02 0.6 0.4
              }
            }
          ]
          name "box_wall_3"
          boundingObject USE box_wall
        }
        Solid {
          translation -0.4 -3.55826007184602e-21 -6.278396306458323e-06
          rotation 0.9807014561659081 -0.19272835386804643 -0.032869978542439886 2.889496319432257e-15
          children [
            DEF d_back Solid {
              translation -0.000334464 -0.15 -0.16
              rotation 0 0 1 3.14
              children [
                DEF distance_sensor_shape Shape {
                  appearance PBRAppearance {
                    baseColor 0 0 0
                    roughness 1
                    metalness 0
                  }
                  geometry Box {
                    size 0.03 0.02 0.02
                  }
                }
                DistanceSensor {
                  name "distance_sensor_back_wall_right"
                  lookupTable [
                    0 0 0
                    0.4 100 0
                  ]
                }
              ]
            }
            DEF d_back Solid {
              translation 0.000127412 0.14 -0.16
              rotation 0 0 1 3.14
              children [
                DEF distance_sensor_shape Shape {
                  appearance PBRAppearance {
                    baseColor 0 0 0
                    roughness 1
                    metalness 0
                  }
                  geometry Box {
                    size 0.03 0.02 0.02
                  }
                }
                DistanceSensor {
                  name "distance_sensor_back_wall_left"
                  lookupTable [
                    0 0 0
                    0.4 100 0
                  ]
                }
              ]
              name "solid(1)"
            }
            DEF box_wall Shape {
              appearance PBRAppearance {
                roughness 1
                metalness 0
              }
              geometry Box {
                size 0.02 0.4 0.4
              }
            }
          ]
          name "box_wall_4"
          boundingObject USE box_wall
        }
        Solid {
          translation -0.26 0 -0.179968
          rotation 0 1 0 1.57
          children [
            DEF box_floor Shape {
              appearance PBRAppearance {
                roughness 1
                metalness 0
              }
              geometry Box {
                size 0.02 0.4 0.3
              }
            }
          ]
          name "box_floor"
          boundingObject USE box_floor
          physics Physics {
            mass 20
          }
        }
      ]
    }
    SliderJoint {
      jointParameters JointParameters {
      }
      device [
        PositionSensor {
          name "slider_position"
        }
        LinearMotor {
          name "slab_linear_motor"
        }
      ]
      endPoint Solid {
        translation -5.586806342849915e-05 -5.213551539044042e-06 -6.423223229967689e-07
        rotation 0.06241781971068871 0.5964172696653762 -0.8002439979327939 2.412764503080983e-06
        children [
          HingeJoint {
            jointParameters HingeJointParameters {
              axis 0 1 0
              anchor -0.15 0 -0.19
            }
            device [
              PositionSensor {
                name "slab_rotational_position"
              }
              RotationalMotor {
                name "slab_rotational_motor"
              }
            ]
            endPoint Solid {
              translation 0.010002000000000039 6.6567e-16 -0.199976
              rotation 0 1 0 0
              children [
                DEF sliding_slab_shape Shape {
                  appearance PBRAppearance {
                    roughness 1
                    metalness 0
                  }
                  geometry Box {
                    size 0.32 0.4 0.015
                  }
                }
              ]
              boundingObject USE sliding_slab_shape
            }
          }
        ]
        name "solid(1)"
      }
    }
  ]
  physics Physics {
  }
  controller "robot_controller"
}
Floor {
  appearance Parquetry {
    type "light strip"
  }
}
Wall {
  translation 5 0 0
  size 0.2 10 1
}
Wall {
  translation -5 0 0
  name "wall(1)"
  size 0.2 10 1
}
Wall {
  translation 0 5 0
  rotation 0 0 1 1.5708
  name "wall(2)"
  size 0.2 10 1
}
Wall {
  translation 0 -5 0
  rotation 0 0 1 1.5708
  name "wall(3)"
  size 0.2 10 1
}
Can {
  translation 3.08425 0.42115 0.061031329999999995
  rotation 1.36827218703902e-14 2.916683094156041e-14 0.9999999999999999 0.00048109782330176627
  name "can(2)"
}
Can {
  translation -0.95662 2.17932 0.061031329999999995
  rotation 1.368977880379217e-14 5.850362307595455e-14 1 0.0004810978233024877
  name "can(1)"
}
Can {
  translation -2.63575 0.418399 0.061031329999999995
  rotation 1.36827218703902e-14 2.916683094156041e-14 0.9999999999999999 0.00048109782330176627
  name "can(3)"
}
Can {
  translation -1.90451 -2.14128 0.0610313
  rotation 6.631786318320845e-15 2.436483143149476e-14 0.9999999999999999 0.00048109782330230496
  name "can(4)"
}
Can {
  translation 0.425049 -1.19009 0.0610313
  rotation 1.368930433950626e-14 5.653119926922873e-14 1 0.00048109782330231103
  name "can(5)"
}
Can {
  translation 2.54581 -2.81925 0.0610313
  rotation 3.1307760674520636e-14 3.161004921168112e-14 1 0.0004810978233023005
  name "can(6)"
}
Can {
  translation -2.7369 2.94841 0.0610313
  rotation 1.368930433950626e-14 5.653119926922873e-14 1 0.00048109782330231103
  name "can(7)"
}
